Workbook

Sheet Resumo
B2: RESUMO DA CARTEIRA
B3: Renda Variável
B4: Capital Investido | C4: ='Carteira RV'!F26 -> 102492.36 | D4: Capital Atual | E4: ='Carteira RV'!G26 -> 125423.57 | G4: Lucro não realizado | H4: ='Carteira RV'!J26 -> 20963.148 | I4: Lucro realizado | K4: =SUM(Vendas!J4:J219) -> -1484.0649
B58: Renda Fixa
B59: Capital Investido | D59: ='Carteira RF'!E9 -> 158019.23 | G59: Capital Atual | J59: ='Carteira RF'!F9 -> 177011.31
B84: Resumo Geral
W261: Renda Variável | X261: =E4 -> 125423.57
W262: Renda Fixa | X262: =J59 -> 177011.31

Sheet Carteira RV
B2: ATIVOS EM CARTEIRA
B3: Código | C3: Nome | D3: Qtde | E3: Preço Médio | F3: Valor Investido | G3: Valor atual | H3: Cotação atual | I3: Rendimento % | J3: Resultado R$ | K3: Tipo de Ativo | L3: Setor
B4: =NFLX!C2 -> NFLX | C4: =NFLX!F2 -> Netflix Inc | D4: =NFLX!J12 -> 8.2276567 | E4: =NFLX!J16*C30 -> 577.82763 | F4: =NFLX!J12*NFLX!J16*C30 -> 4754.1673 | G4: =IF(D4="","",D4*H4) -> 3037.1022 | H4: =IFERROR(__xludf.DUMMYFUNCTION("IF(B5="""","""",GOOGLEFINANCE(B4))*C30"),369.133315) -> 369.13331 | I4: =IF(J4="","",J4/F4) -> -0.36117053 | J4: =IF(G4="","",G4-F4) -> -1717.0651 | K4: =IF(B4="","",VLOOKUP(B4,DB!$A$4:$G$1906,7,0)) -> Stock | L4: =IF(B4="","",VLOOKUP(B4,DB!$A$4:$G$1906,6,0)) -> EUA
B5: =AAPL!C2 -> AAPL | C5: =AAPL!F2 -> Apple Inc | D5: =AAPL!J12 -> 5.7527207 | E5: =AAPL!J16*C30 -> 1167.1215 | F5: =AAPL!J12*AAPL!J16*C30 -> 6714.1238 | G5: =IF(D5="","",D5*H5) -> 10179.47 | H5: =IFERROR(__xludf.DUMMYFUNCTION("IF(B5="""","""",GOOGLEFINANCE(B5))*C30"),1769.5052669999998) -> 1769.5053 | I5: =IF(J5="","",J5/F5) -> 0.51612778 | J5: =IF(G5="","",G5-F5) -> 3465.3458 | K5: Stock | L5: Electronic Components
B6: =META!C2 -> META | C6: =META!F2 -> Meta Platforms Inc | D6: =META!J12 -> 1.2685955 | E6: =META!J16*C30 -> 3747.5832 | F6: =META!J12*META!J16*C30 -> 4754.1673 | G6: =IF(D6="","",D6*H6) -> 4947.1259 | H6: =IFERROR(__xludf.DUMMYFUNCTION("IF(B6="""","""",GOOGLEFINANCE(B6))*C30"),3899.6872459999995) -> 3899.6872 | I6: =IF(J6="","",J6/F6) -> 0.040587249 | J6: =IF(G6="","",G6-F6) -> 192.95857 | K6: =IF(B6="","",VLOOKUP(B6,DB!$A$4:$G$1906,7,0)) -> Stock | L6: =IF(B6="","",VLOOKUP(B6,DB!$A$4:$G$1906,6,0)) -> EUA
B7: =FAST!C2 -> FAST | C7: =FAST!F2 -> Fastenal Co | D7: =FAST!J12 -> 32.423903 | E7: =FAST!J16*C30 -> 203.54498 | F7: =FAST!J12*FAST!J16*C30 -> 6599.7227 | G7: =IF(D7="","",D7*H7) -> 8483.2564 | H7: =IFERROR(__xludf.DUMMYFUNCTION("IF(B7="""","""",GOOGLEFINANCE(B7))*C30"),261.635883) -> 261.63588 | I7: =IF(J7="","",J7/F7) -> 0.28539589 | J7: =IF(G7="","",G7-F7) -> 1883.5337 | K7: =IF(B7="","",VLOOKUP(B7,DB!$A$4:$G$1906,7,0)) -> Stock | L7: =IF(B7="","",VLOOKUP(B7,DB!$A$4:$G$1906,6,0)) -> Industrial Distribution
B8: =APH!C2 -> APH | C8: =APH!F2 -> Amphenol Corp | D8: =APH!J12 -> 27.644698 | E8: =APH!J16*C30 -> 237.08342 | F8: =APH!J12*APH!J16*C30 -> 6554.0995 | G8: =IF(D8="","",D8*H8) -> 12060.478 | H8: =IFERROR(__xludf.DUMMYFUNCTION("IF(B8="""","""",GOOGLEFINANCE(B8))*C30"),436.26732899999996) -> 436.26733 | I8: =IF(J8="","",J8/F8) -> 0.84014271 | J8: =IF(G8="","",G8-F8) -> 5506.3789 | K8: =IF(B8="","",VLOOKUP(B8,DB!$A$4:$G$1906,7,0)) -> Stock | L8: =IF(B8="","",VLOOKUP(B8,DB!$A$4:$G$1906,6,0)) -> Electronic Components
B9: =KO!C2 -> KO | C9: =KO!F2 -> Coca-Cola Co | D9: =KO!J12 -> 19.252848 | E9: =KO!J16*C30 -> 350.72627 | F9: =KO!J12*KO!J16*C30 -> 6752.4797 | G9: =IF(D9="","",D9*H9) -> 8770.9635 | H9: =IFERROR(__xludf.DUMMYFUNCTION("IF(B9="""","""",GOOGLEFINANCE(B9))*C30"),455.56706099999997) -> 455.56706 | I9: =IF(J9="","",J9/F9) -> 0.29892484 | J9: =IF(G9="","",G9-F9) -> 2018.4839 | K9: =IF(B9="","",VLOOKUP(B9,DB!$A$4:$G$1906,7,0)) -> Stock | L9: =IF(B9="","",VLOOKUP(B9,DB!$A$4:$G$1906,6,0)) -> Non-Alcoholic beverages
B10: =VISC11!C2 -> VISC11 | C10: =VISC11!F2 -> Vinci Shopping Centers FI Imobiliario | D10: =VISC11!J12 -> 42 | E10: =VISC11!J16 -> 107.63071 | F10: =VISC11!J12*VISC11!J16 -> 4520.49 | G10: =IF(D10="","",D10*H10) -> 4318.02 | H10: =IFERROR(__xludf.DUMMYFUNCTION("IF(B10="""","""",GOOGLEFINANCE(B10))"),102.81) -> 102.81 | I10: =IF(J10="","",J10/F10) -> -0.044789392 | J10: =IF(G10="","",G10-F10) -> -202.47 | K10: =IF(B10="","",VLOOKUP(B10,DB!$A$4:$G$1906,7,0)) -> Fii | L10: =IF(B10="","",VLOOKUP(B10,DB!$A$4:$G$1906,6,0)) -> BRL Trust DTVM
B11: =KNRI11!C2 -> KNRI11 | C11: =KNRI11!F2 -> Kinea Renda Imobiliaria FII | D11: =KNRI11!J12 -> 30 | E11: =KNRI11!J16 -> 145.71 | F11: =KNRI11!J12*KNRI11!J16 -> 4371.3 | G11: =IF(D11="","",D11*H11) -> 4687.2 | H11: =IFERROR(__xludf.DUMMYFUNCTION("IF(B11="""","""",GOOGLEFINANCE(B11))"),156.24) -> 156.24 | I11: =IF(J11="","",J11/F11) -> 0.072266831 | J11: =IF(G11="","",G11-F11) -> 315.9 | K11: =IF(B11="","",VLOOKUP(B11,DB!$A$4:$G$1906,7,0)) -> Fii | L11: =IF(B11="","",VLOOKUP(B11,DB!$A$4:$G$1906,6,0)) -> INTRAG
B12: =HGRU11!C2 -> HGRU11 | C12: =HGRU11!F2 -> Patria Renda Urbana FII RL Unica | D12: =HGRU11!J12 -> 39 | E12: =HGRU11!J16 -> 124.41051 | F12: =HGRU11!J12*HGRU11!J16 -> 4852.01 | G12: =IF(D12="","",D12*H12) -> 4438.98 | H12: =IFERROR(__xludf.DUMMYFUNCTION("IF(B12="""","""",GOOGLEFINANCE(B12))"),113.82) -> 113.82 | I12: =IF(J12="","",J12/F12) -> -0.085125546 | J12: =IF(G12="","",G12-F12) -> -413.03 | K12: =IF(B12="","",VLOOKUP(B12,DB!$A$4:$G$1906,7,0)) -> Fii | L12: =IF(B12="","",VLOOKUP(B12,DB!$A$4:$G$1906,6,0)) -> CREDIT SUISSE
B13: =HGLG11!C2 -> HGLG11 | C13: =HGLG11!F2 -> Patria Log FII RL | D13: =HGLG11!J12 -> 28 | E13: =HGLG11!J16 -> 157.94214 | F13: =HGLG11!J12*HGLG11!J16 -> 4422.38 | G13: =IF(D13="","",D13*H13) -> 4140.08 | H13: =IFERROR(__xludf.DUMMYFUNCTION("IF(B13="""","""",GOOGLEFINANCE(B13))"),147.86) -> 147.86 | I13: =IF(J13="","",J13/F13) -> -0.063834406 | J13: =IF(G13="","",G13-F13) -> -282.3 | K13: =IF(B13="","",VLOOKUP(B13,DB!$A$4:$G$1906,7,0)) -> Fii | L13: =IF(B13="","",VLOOKUP(B13,DB!$A$4:$G$1906,6,0)) -> CREDIT SUISSE
B14: =B3SA3!C2 -> B3SA3 | C14: =B3SA3!F2 -> B3 SA Brasil Bolsa Balcao | D14: =B3SA3!J12 -> 386 | E14: =B3SA3!J16 -> 12.484326 | F14: =B3SA3!J12*B3SA3!J16 -> 4818.95 | G14: =IF(D14="","",D14*H14) -> 6932.56 | H14: =IFERROR(__xludf.DUMMYFUNCTION("IF(B14="""","""",GOOGLEFINANCE(B14))"),17.96) -> 17.96 | I14: =IF(J14="","",J14/F14) -> 0.43860385 | J14: =IF(G14="","",G14-F14) -> 2113.61 | K14: =IF(B14="","",VLOOKUP(B14,DB!$A$4:$G$1906,7,0)) -> Ação | L14: =IF(B14="","",VLOOKUP(B14,DB!$A$4:$G$1906,6,0)) -> Serviços Financeiros Diversos
B15: =WEGE3!C2 -> WEGE3 | C15: =WEGE3!F2 -> Weg Cedear | D15: =WEGE3!J12 -> 126 | E15: =WEGE3!J16 -> 42.027381 | F15: =WEGE3!J12*WEGE3!J16 -> 5295.45 | G15: =IF(D15="","",D15*H15) -> 6434.82 | H15: =IFERROR(__xludf.DUMMYFUNCTION("IF(B15="""","""",GOOGLEFINANCE(""BVMF:""&B15))"),51.07) -> 51.07 | I15: =IF(J15="","",J15/F15) -> 0.21516018 | J15: =IF(G15="","",G15-F15) -> 1139.37 | K15: =IF(B15="","",VLOOKUP(B15,DB!$A$4:$G$1906,7,0)) -> Ação | L15: =IF(B15="","",VLOOKUP(B15,DB!$A$4:$G$1906,6,0)) -> Motores, Compressores e Outros
B16: =TAEE3!C2 -> TAEE3 | C16: =TAEE3!F2 -> Transmissora Alianca de Enrga Eltrca S/A | D16: =TAEE3!J12 -> 406 | E16: =TAEE3!J16 -> 12.204655 | F16: =TAEE3!J12*TAEE3!J16 -> 4955.09 | G16: =IF(D16="","",D16*H16) -> 5440.4 | H16: =IFERROR(__xludf.DUMMYFUNCTION("IF(B16="""","""",GOOGLEFINANCE(B16))"),13.4) -> 13.4 | I16: =IF(J16="","",J16/F16) -> 0.097941712 | J16: =IF(G16="","",G16-F16) -> 485.31 | K16: =IF(B16="","",VLOOKUP(B16,DB!$A$4:$G$1906,7,0)) -> Ação | L16: =IF(B16="","",VLOOKUP(B16,DB!$A$4:$G$1906,6,0)) -> Energia Elétrica
B17: =PSSA3!C2 -> PSSA3 | C17: =PSSA3!F2 -> Porto Seguro SA | D17: =PSSA3!J12 -> 120 | E17: =PSSA3!J16 -> 33.16125 | F17: =PSSA3!J12*PSSA3!J16 -> 3979.35 | G17: =IF(D17="","",D17*H17) -> 5650.8 | H17: =IFERROR(__xludf.DUMMYFUNCTION("IF(B17="""","""",GOOGLEFINANCE(B17))"),47.09) -> 47.09 | I17: =IF(J17="","",J17/F17) -> 0.42003091 | J17: =IF(G17="","",G17-F17) -> 1671.45 | K17: =IF(B17="","",VLOOKUP(B17,DB!$A$4:$G$1906,7,0)) -> Ação | L17: =IF(B17="","",VLOOKUP(B17,DB!$A$4:$G$1906,6,0)) -> Seguradoras
B18: =ITUB3!C2 -> ITUB3 | C18: =ITUB3!F2 -> Itau Unibanco Holding Cedear | D18: =ITUB3!J12 -> 142 | E18: =ITUB3!J16 -> 29.209718 | F18: =ITUB3!J12*ITUB3!J16 -> 4147.78 | G18: =IF(D18="","",D18*H18) -> 6544.78 | H18: =IFERROR(__xludf.DUMMYFUNCTION("IF(B18="""","""",GOOGLEFINANCE(""BVMF:""&B18))"),46.09) -> 46.09 | I18: =IF(J18="","",J18/F18) -> 0.5778995 | J18: =IF(G18="","",G18-F18) -> 2397 | K18: =IF(B18="","",VLOOKUP(B18,DB!$A$4:$G$1906,7,0)) -> Ação | L18: =IF(B18="","",VLOOKUP(B18,DB!$A$4:$G$1906,6,0)) -> Bancos
B19: =HYPE3!C2 -> HYPE3 | C19: =HYPE3!F2 -> Hypera SA | D19: =HYPE3!J12 -> 211 | E19: =HYPE3!J16 -> 25.613554 | F19: =HYPE3!J12*HYPE3!J16 -> 5404.46 | G19: =IF(D19="","",D19*H19) -> 5175.83 | H19: =IFERROR(__xludf.DUMMYFUNCTION("IF(B19="""","""",GOOGLEFINANCE(B19))"),24.53) -> 24.53 | I19: =IF(J19="","",J19/F19) -> -0.042303949 | J19: =IF(G19="","",G19-F19) -> -228.63 | K19: =IF(B19="","",VLOOKUP(B19,DB!$A$4:$G$1906,7,0)) -> Ação | L19: =IF(B19="","",VLOOKUP(B19,DB!$A$4:$G$1906,6,0)) -> Medicamentos e Outros Produtos
B20: =EGIE3!C2 -> EGIE3 | C20: =EGIE3!F2 -> Engie Brasil Energia SA | D20: =EGIE3!J12 -> 161 | E20: =EGIE3!J16 -> 29.905081 | F20: =EGIE3!J12*EGIE3!J16 -> 4814.718 | G20: =IF(D20="","",D20*H20) -> 4685.1 | H20: =IFERROR(__xludf.DUMMYFUNCTION("IF(B20="""","""",GOOGLEFINANCE(B20))"),29.1) -> 29.1 | I20: =IF(J20="","",J20/F20) -> -0.026921203 | J20: =IF(G20="","",G20-F20) -> -129.618 | K20: =IF(B20="","",VLOOKUP(B20,DB!$A$4:$G$1906,7,0)) -> Ação | L20: =IF(B20="","",VLOOKUP(B20,DB!$A$4:$G$1906,6,0)) -> Energia Elétrica
B21: =BBDC3!C2 -> BBDC3 | C21: =BBDC3!F2 -> Banco Bradesco Cedear | D21: =BBDC3!J12 -> 376 | E21: =BBDC3!J16 -> 13.606782 | F21: =BBDC3!J12*BBDC3!J16 -> 5116.15 | G21: =IF(D21="","",D21*H21) -> 5929.52 | H21: =IFERROR(__xludf.DUMMYFUNCTION("IF(B21="""","""",GOOGLEFINANCE(""BVMF:""&B21))"),15.77) -> 15.77 | I21: =IF(J21="","",J21/F21) -> 0.15898087 | J21: =IF(G21="","",G21-F21) -> 813.37 | K21: =IF(B21="","",VLOOKUP(B21,DB!$A$4:$G$1906,7,0)) -> Ação | L21: =IF(B21="","",VLOOKUP(B21,DB!$A$4:$G$1906,6,0)) -> Bancos
B22: =ABEV3!C2 -> ABEV3 | C22: =ABEV3!F2 -> Amebv Cedear | D22: =ABEV3!J12 -> 378 | E22: =ABEV3!J16 -> 13.286032 | F22: =ABEV3!J12*ABEV3!J16 -> 5022.12 | G22: =IF(D22="","",D22*H22) -> 5790.96 | H22: =IFERROR(__xludf.DUMMYFUNCTION("IF(B22="""","""",GOOGLEFINANCE(""BVMF:""&B22))"),15.32) -> 15.32 | I22: =IF(J22="","",J22/F22) -> 0.15309073 | J22: =IF(G22="","",G22-F22) -> 768.84 | K22: =IF(B22="","",VLOOKUP(B22,DB!$A$4:$G$1906,7,0)) -> Ação | L22: =IF(B22="","",VLOOKUP(B22,DB!$A$4:$G$1906,6,0)) -> Cervejas e Refrigerantes
B23: =BTC!C2 -> BTCUSD | C23: =BTC!F2 -> Bitcoin | D23: =BTC!J12 -> 0.00763929 | E23: =BTC!J16 -> 159254.36 | F23: =BTC!J13 -> 2667.144 | G23: =IF(D23="","",D23*H23) -> 3355.4548 | H23: =IFERROR(__xludf.DUMMYFUNCTION("IF(B23="""","""",(GOOGLEFINANCE(B23)*C30))"),439236.47862999997) -> 439236.48 | I23: =IF(J23="","",J23/F23) -> 0.25807037 | J23: =IF(G23="","",G23-F23) -> 688.31083 | K23: =IF(B23="","",VLOOKUP(B23,DB!$A$4:$G$1906,7,0)) -> Criptomoeda | L23: =IF(B23="","",VLOOKUP(B23,DB!$A$4:$G$1906,6,0)) -> Criptos
B24: =ETH!C2 -> ETHUSD | C24: =ETH!F2 -> Ethereum | D24: =ETH!J12 -> 0.17436968 | E24: =ETH!J16 -> 6284.174 | F24: =ETH!J13 -> 1976.2118 | G24: =IF(D24="","",D24*H24) -> 2452.6115 | H24: =IFERROR(__xludf.DUMMYFUNCTION("IF(B24="""","""",(GOOGLEFINANCE(B24)*C30))"),14065.58449964) -> 14065.585 | I24: =IF(J24="","",J24/F24) -> 0.24106713 | J24: =IF(G24="","",G24-F24) -> 476.39969 | K24: =IF(B24="","",VLOOKUP(B24,DB!$A$4:$G$1906,7,0)) -> Criptomoeda | L24: =IF(B24="","",VLOOKUP(B24,DB!$A$4:$G$1906,6,0)) -> Criptos
B25: =PAXGOLD!C2 -> Pax Gold | C25: Pax Gold | D25: =PAXGOLD!J12 -> 0.07249708 | E25: =PAXGOLD!J16 -> 26388.536 | F25: =PAXGOLD!J13 -> 1912.5989 | G25: =IF(D25="","",D25*H25) -> 1968.0594 | H25: 27146.74 | I25: =IF(J25="","",J25/F25) -> 0.028997437 | J25: =IF(G25="","",G25-F25) -> 55.460467 | K25: Criptomoeda | L25: Criptos
B26: Total | F26: =SUM(F4:F24) -> 102492.36 | G26: =SUM(G4:G25) -> 125423.57 | H26: - | I26: =AVERAGE(I4:I22) -> 0.18373726 | J26: =SUM(J4:J24) -> 20963.148 | K26: - | L26: -
B30: Valor Dólar | C30: =IFERROR(__xludf.DUMMYFUNCTION("GOOGLEFINANCE(""CURRENCY:USDBRL"")"),5.1880999999999995) -> 5.1881

Sheet Carteira RF
B2: APLICAÇÕES EM CARTEIRA
B3: Código | C3: Nome | D3: Tipo de aplicação | E3: Valor Bruto Investido | F3: Valor Líquido atual | G3: Valorizacão R$ | H3: Valorização %
B4: ='Tesouro Selic 2027'!C2 -> TS2027 | C4: ='Tesouro Selic 2027'!E2 -> Tesouro Selic 2027 | D4: Tesouro Direto | E4: ='Tesouro Selic 2027'!J3 -> 29884.98 | F4: ='Tesouro Selic 2027'!J4 -> 38297.07 | G4: ='Tesouro Selic 2027'!J5 -> 8412.09 | H4: ='Tesouro Selic 2027'!J6 -> 0.2814822
B5: ='Tesouro Renda+ 2055'!C2 -> TR+2055 | C5: ='Tesouro Renda+ 2055'!E2 -> Tesouro Renda+ 2055 | D5: Tesouro Direto | E5: ='Tesouro Renda+ 2055'!J3 -> 6449.86 | F5: ='Tesouro Renda+ 2055'!J4 -> 6154.86 | G5: ='Tesouro Renda+ 2055'!J5 -> -295 | H5: ='Tesouro Renda+ 2055'!J6 -> -0.045737427
B6: ='Tesouro Educa+ 2043'!C2 -> TE+2043 | C6: ='Tesouro Educa+ 2043'!E2 -> Tesouro Educa+ 2043 | D6: Tesouro Direto | E6: ='Tesouro Educa+ 2043'!J3 -> 3794.23 | F6: ='Tesouro Educa+ 2043'!J4 -> 3786.53 | G6: ='Tesouro Educa+ 2043'!J5 -> -7.7 | H6: ='Tesouro Educa+ 2043'!J6 -> -0.0020293973
B7: ='Tesouro Selic 2028'!C2 -> TS2028 | C7: ='Tesouro Selic 2028'!E2 -> Tesouro Selic 2028 | D7: Tesouro Direto | E7: ='Tesouro Selic 2028'!J3 -> 67343.78 | F7: ='Tesouro Selic 2028'!J4 -> 75978.29 | G7: ='Tesouro Selic 2028'!J5 -> 8634.51 | H7: ='Tesouro Selic 2028'!J6 -> 0.1282154
B8: ='Tesouro Selic 2031'!C2 -> TS2031 | C8: ='Tesouro Selic 2031'!E2 -> Tesouro Selic 2031 | D8: =IF(B8="","",VLOOKUP(B8,DB!$A$4:$G$1906,7,0)) -> Tesouro Direto | E8: ='Tesouro Selic 2031'!J3 -> 50546.38 | F8: ='Tesouro Selic 2031'!J4 -> 52794.56 | G8: ='Tesouro Selic 2031'!J5 -> 2248.18 | H8: ='Tesouro Selic 2031'!J6 -> 0.044477567
B9: Total | E9: =SUM(E4:E8) -> 158019.23 | F9: =SUM(F4:F8) -> 177011.31 | G9: =SUM(G4:G8) -> 18992.08 | H9: =SUM(H4:H8)/COUNT(H4:H8) -> 0.08128167

Sheet AtivoChove
B2: ID | C2: ITUB3 | D2: Nome do Ativo | F2: =IFERROR(__xludf.DUMMYFUNCTION("IF(C2="""","""",GOOGLEFINANCE(C2,""Name""))"),"Itau Unibanco Holding Cedear") -> Itau Unibanco Holding Cedear
B3: Data | C3: Operação | D3: Qtde | E3: Valor unitário | F3: Taxas/Impostos | G3: Valor da operação | H3: Gráfico | K3: Dias graf
G4: =E4*D4 -> 0 | H4: =IFERROR(__xludf.DUMMYFUNCTION("IF(C2="""","""",SPARKLINE(GOOGLEFINANCE(C2,""price"",TODAY()-K4,TODAY())))"),"") | K4: 30
I10: Qtde Comprada | J10: =SUMIFS(D4:D21,C4:C21,"COMPRA") -> 0
I11: Qtde Vendida | J11: =SUMIFS(D4:D21,C4:C21,"VENDA") -> 0
I12: Qtde em Carteira | J12: =J10-J11 -> 0
I13: Valor das Compras | J13: =SUMIFS(G4:G21,C4:C21,"COMPRA") -> 0
I14: Valor das Vendas | J14: =SUMIFS(E4:E21,C4:C21,"VENDA") -> 0
I15: Total de Taxas | J15: =SUM(F4:F21) -> 0
I16: Preço Médio | J16: =IF(J10<>0,((J13+J15)/J10),"")

Sheet Vendas
B2: VENDA DE ATIVOS
B3: Tipo de negociação | C3: Código | D3: Preço médio de compra | E3: Preço de venda | F3: Qtde | G3: Valor bruto da Compra | H3: Valor bruto da Venda | I3: Taxa | J3: Lucro líquido | K3: Mês/ano da venda
B4: Venda | C4: LTC | D4: 511.75458 | E4: 313.87 | F4: 2.44145 | G4: =F4*D4 -> 1249.4232 | H4: =F4*E4 -> 766.29791 | I4: 5.27 | J4: =(E4-D4)*F4-I4 -> -488.3953 | K4: 44718
B5: Venda | C5: ETH | D5: 12975.982 | E5: 9125.77 | F5: 0.14231757 | G5: =F5*D5 -> 1846.7102 | H5: =F5*E5 -> 1298.7574 | I5: 8.98 | J5: =(E5-D5)*F5-I5 -> -556.93279 | K5: 44718
B6: Venda | C6: BTC | D6: 196789.07 | E6: 150000 | F6: 0.00916938 | G6: =F6*D6 -> 1804.4338 | H6: =F6*E6 -> 1375.407 | I6: 9.71 | J6: =(E6-D6)*F6-I6 -> -438.73677 | K6: 44718

Sheet Evolução Patrimônio
B2: Evolução de patrimônio
B3: Mês | C3: Total Investido no mês | D3: Total retirado no período | E3: Alocação líquida | F3: Patrimônio total | G3: Evolução patrimonial | H3: %
B4: 44621 | C4: 5607.59 | D4: 0 | E4: =C4-D4 -> 5607.59 | F4: =62107.17+E4 -> 67714.76 | G4: =F4-62107.17 -> 5607.59 | H4: =G4/F4 -> 0.082811931
B5: 44652 | C5: 4000 | D5: =12769+946 -> 13715 | E5: =C5-D5 -> -9715 | F5: =F4+E5 -> 57999.76 | G5: =F5-F4 -> -9715 | H5: =G5/F4 -> -0.14346946
B6: 44682 | C6: 0 | D6: 9812 | E6: =C6-D6 -> -9812 | F6: =F5+E6 -> 48187.76 | G6: =F6-F5 -> -9812 | H6: =G6/F5 -> -0.16917311
B7: 44713 | C7: 0 | D7: =1484.06+4515.55 -> 5999.61 | E7: =C7-D7 -> -5999.61 | F7: =F6+E7 -> 42188.15 | G7: =F7-F6 -> -5999.61 | H7: =G7/F6 -> -0.12450485
B8: 44743 | C8: 8935.5 | D8: 1500 | E8: =C8-D8 -> 7435.5 | F8: 49518.77 | G8: =F8-F7 -> 7330.62 | H8: =G8/F7 -> 0.17376017
B9: 44774 | C9: 0 | D9: 500 | E9: =C9-D9 -> -500 | F9: =42137.81+6729.22 -> 48867.03 | G9: =F9-F8 -> -651.74 | H9: =G9/F8 -> -0.013161474
B10: 44805 | C10: 7050 | D10: 846 | E10: =C10-D10 -> 6204 | F10: 56110.88 | G10: =F10-F9 -> 7243.85 | H10: =G10/F9 -> 0.14823594
B11: 44927 | C11: 6301 | D11: 0 | E11: =C11-D11 -> 6301 | F11: =10387.24+51310.66 -> 61697.9 | G11: =F11-F10 -> 5587.02 | H11: =G11/F10 -> 0.099571064
B12: 44958 | C12: 0 | D12: =1332.87+899.47 -> 2232.34 | E12: =C12-D12 -> -2232.34 | F12: =61697.9+E12 -> 59465.56 | G12: =F12-F11 -> -2232.34 | H12: =G12/F11 -> -0.036181783
B13: 44986 | C13: 4000 | D13: 0 | E13: =C13-D13 -> 4000 | F13: =F12+E13 -> 63465.56 | G13: =F13-F12 -> 4000 | H13: =G13/F12 -> 0.067265826
B14: 45047 | C14: 0 | D14: 0 | E14: =C14-D14 -> 0 | F14: =67000 -> 67000 | G14: =F14-F13 -> 3534.44 | H14: =G14/F13 -> 0.055690677
B15: 45139 | C15: 0 | D15: =5620+22243.59 -> 27863.59 | E15: =C15-D15 -> -27863.59 | F15: =14986.38+40857.9 -> 55844.28 | G15: =F15-F14 -> -11155.72 | H15: =G15/F14 -> -0.16650328
B16: 45231 | C16: =1174.98+6973.65+259.59 -> 8408.22 | D16: 0 | E16: =C16-D16 -> 8408.22 | F16: =19049.055349075+43723.33 -> 62772.385 | G16: =F16-F15 -> 6928.1053 | H16: =G16/F15 -> 0.12406115
B17: 45292 | C17: 6640 | D17: 1149.47 | E17: =C17-D17 -> 5490.53 | F17: 71457.31 | G17: =F17-F16 -> 8684.9247 | H17: =G17/F16 -> 0.13835582
B18: 45323 | C18: =2982.99+12015.08 -> 14998.07 | D18: 0 | E18: =C18-D18 -> 14998.07 | F18: 85081.826 | G18: =F18-F17 -> 13624.516 | H18: =G18/F17 -> 0.19066651
B19: 45352 | C19: 4998.95 | D19: 35453.76 | E19: =C19-D19 -> -30454.81 | F19: =25417.74+30509.27 -> 55927.01 | G19: =F19-F18 -> -29154.816 | H19: =G19/F18 -> -0.34266796
B20: 45413 | C20: =1997.64+1151.13 -> 3148.77 | D20: 0 | E20: =C20-D20 -> 3148.77 | F20: =23804.89+33033.15 -> 56838.04 | G20: =F20-F19 -> 911.03 | H20: =G20/F19 -> 0.016289625
B21: 45505 | C21: =1632.8+2118.54+1032.11 -> 4783.45 | D21: 0 | E21: =C21-D21 -> 4783.45 | F21: =32558.39+42197.3 -> 74755.69 | G21: =F21-F20 -> 17917.65 | H21: =G21/F20 -> 0.31524046
B22: 45536 | C22: 6086.91 | D22: 0 | E22: =C22-D22 -> 6086.91 | F22: =35512.47+48582.99 -> 84095.46 | G22: =F22-F21 -> 9339.77 | H22: =G22/F21 -> 0.12493725
B23: 45566 | C23: 31893.23 | D23: =2018.79+4195.74 -> 6214.53 | E23: =C23-D23 -> 25678.7 | F23: =46543.65+62145.89 -> 108689.54 | G23: =F23-F22 -> 24594.08 | H23: =G23/F22 -> 0.29245431
B24: 45597 | C24: 8957.03 | D24: 0 | E24: =C24-D24 -> 8957.03 | F24: =50581.3+66589.87 -> 117171.17 | G24: =F24-F23 -> 8481.63 | H24: =G24/F23 -> 0.078035384
B25: 45658 | C25: 12427.15 | D25: 0 | E25: =C25-D25 -> 12427.15 | F25: =54177.43+72735.81 -> 126913.24 | G25: =F25-F24 -> 9742.07 | H25: =G25/F24 -> 0.083143917
B26: 45748 | C26: 8913.13 | D26: 0 | E26: =C26-D26 -> 8913.13 | F26: =58288.94+77084.23 -> 135373.17 | G26: =F26-F25 -> 8459.93 | H26: =G26/F25 -> 0.06665916
B27: 45839 | C27: 16130.44 | D27: 0 | E27: =C27-D27 -> 16130.44 | F27: =69608.91+95124.65 -> 164733.56 | G27: =F27-F26 -> 29360.39 | H27: =G27/F26 -> 0.21688485
B28: 45901 | C28: =2887.65+'Tesouro Selic 2028'!D6+(642*'Carteira RV'!C30) -> 16652.32 | D28: 0 | E28: =C28-D28 -> 16652.32 | F28: =71079.93+96975.42+E28 -> 184707.67 | G28: =F28-F27 -> 19974.11 | H28: =G28/F27 -> 0.12125101
B29: 45931 | C29: =(366*'Carteira RV'!C30)+3009.21+'Tesouro Selic 2028'!D7 -> 10863.305 | D29: 0 | E29: =C29-D29 -> 10863.305 | F29: =81107.39+119550.43 -> 200657.82 | G29: =F29-F28 -> 15950.15 | H29: =G29/F28 -> 0.086353478
B30: 46023 | C30: =3126.31+3006.12+16999.7+2499 -> 25631.13 | D30: 0 | E30: =C30-D30 -> 25631.13 | F30: =105040.19+139032.29 -> 244072.48 | G30: =F30-F29 -> 43414.66 | H30: =G30/F29 -> 0.21636166
B31: 46082 | C31: 29618.604 | D31: 0 | E31: =C31-D31 -> 29618.604 | F31: =111213.65+175393.41 -> 286607.06 | G31: =F31-F30 -> 42534.58 | H31: =G31/F30 -> 0.17427028
B32: 46204 | C32: =((AAPL!G16+AAPL!G15+FAST!G18+KO!G17+APH!G16+APH!G17)*'Carteira RV'!C30)+(EGIE3!G25+KNRI11!G24+HGRU11!G25+HGLG11!G25+ITUB3!G23+WEGE3!G26+TAEE3!G26+PSSA3!G21+HYPE3!G27+B3SA3!G27+BBDC3!G27+ABEV3!G26+'Tesouro Selic 2031'!D7+'Tesouro Educa+ 2043'!D4+'Tesouro Renda+ 2055'!D4) -> 36981.927 | D32: =SUM('Tesouro Selic 2031'!D6+'Tesouro IPCA+ 2035'!D21) -> -38526.94 | E32: =C32+D32 -> -1545.013 | F32: =120984.13+167991.3 -> 288975.43 | G32: =F32-F31 -> 2368.37 | H32: =G32/F31 -> 0.008263474
B33: 46266 | C33: =3168.1+637.07+2149.32 -> 5954.49 | D33: 0 | E33: =C33+D33 -> 5954.49 | F33: =124151.31+158019.23 -> 282170.54 | G33: =F33-F32 -> -6804.89 | H33: =G33/F32 -> -0.023548334

Sheet AAPL
B2: ID | C2: AAPL | D2: Nome do Ativo | F2: =IFERROR(__xludf.DUMMYFUNCTION("IF(C2="""","""",GOOGLEFINANCE(C2,""Name""))"),"Apple Inc") -> Apple Inc
B3: Data | C3: Operação | D3: Qtde | E3: Valor unitário | F3: Taxas/Impostos | G3: Valor da operação | H3: Gráfico | K3: Dias graf
B4: 44655 | C4: COMPRA | D4: 1 | E4: 117.19 | F4: 0 | G4: =E4*D4 -> 117.19 | H4: =IFERROR(__xludf.DUMMYFUNCTION("IF(C2="""","""",SPARKLINE(GOOGLEFINANCE(C2,""price"",TODAY()-K4,TODAY())))"),"") | K4: 30
B5: 45551 | C5: COMPRA | D5: 0.16 | E5: 216.36 | F5: 0 | G5: =E5*D5 -> 34.6176
B6: 45595 | C6: COMPRA | D6: 0.4894 | E6: 230.88 | F6: 0 | G6: =E6*D6 -> 112.99267
B7: 45628 | C7: COMPRA | D7: 0.2251 | E7: 239.8 | F7: 0 | G7: =E7*D7 -> 53.97898
B8: 45667 | C8: COMPRA | D8: =G8/E8 -> 0.31035339 | E8: 241.66 | F8: 0 | G8: 75
B9: 45758 | C9: COMPRA | D9: =G9/E9 -> 0.25822785 | E9: 197.5 | F9: 0 | G9: 51
B10: 45848 | C10: COMPRA | D10: 1.1184211 | E10: 212.8 | F10: 0 | G10: =E10*D10 -> 238 | I10: Qtde Comprada | J10: =SUMIFS(D4:D21,C4:C21,"COMPRA") -> 5.7527207
B11: 45939 | C11: COMPRA | D11: 0.23921569 | E11: 255 | F11: 0 | G11: =E11*D11 -> 61.000001 | I11: Qtde Vendida | J11: =SUMIFS(D4:D21,C4:C21,"VENDA") -> 0
B12: 46000 | C12: COMPRA | D12: 0.32314818 | E12: 278.51 | F12: 0 | G12: =E12*D12 -> 90 | I12: Qtde em Carteira | J12: =J10-J11 -> 5.7527207
B13: 46051 | C13: COMPRA | D13: 0.37454234 | E13: 256.74 | F13: 0 | G13: =E13*D13 -> 96.16 | I13: Valor das Compras | J13: =SUMIFS(G4:G21,C4:C21,"COMPRA") -> 1294.1393
B14: 46087 | C14: COMPRA | D14: 0.42160224 | E14: 256.64 | F14: 0 | G14: =E14*D14 -> 108.2 | I14: Valor das Vendas | J14: =SUMIFS(E4:E21,C4:C21,"VENDA") -> 0
B15: 46205 | C15: COMPRA | D15: 0.41619249 | E15: 307.55 | F15: 0 | G15: =E15*D15 -> 128 | I15: Total de Taxas | J15: =SUM(F4:F21) -> 0
B16: 46205 | C16: COMPRA | D16: 0.41651752 | E16: 307.31 | F16: 0 | G16: =E16*D16 -> 128 | I16: Preço Médio | J16: =IF(J10<>0,((J13+J15)/J10),"") -> 224.96125
G17: =E17*D17 -> 0
G18: =E18*D18 -> 0
G19: =E19*D19 -> 0
G20: =E20*D20 -> 0
G21: =E21*D21 -> 0

Sheet NFLX
B2: ID | C2: NFLX | D2: Nome do Ativo | F2: =IFERROR(__xludf.DUMMYFUNCTION("IF(C2="""","""",GOOGLEFINANCE(C2,""Name""))"),"Netflix Inc") -> Netflix Inc
B3: Data | C3: Operação | D3: Qtde | E3: Valor unitário | F3: Taxas/Impostos | G3: Valor da operação | H3: Gráfico | K3: Dias graf
B4: 45848 | C4: COMPRA | D4: 1.9168564 | E4: 125.205 | F4: 0 | G4: 240 | H4: =IFERROR(__xludf.DUMMYFUNCTION("IF(C2="""","""",SPARKLINE(GOOGLEFINANCE(C2,""price"",TODAY()-K4,TODAY())))"),"") | K4: 50
B5: 45922 | C5: COMPRA | D5: 2.6184844 | E5: 122.59 | F5: 0 | G5: 321
B6: 45939 | C6: COMPRA | D6: 0.4965001 | E6: 122.86 | F6: 0 | G6: 61
B7: 46000 | C7: COMPRA | D7: 0.9375 | E7: 96 | F7: 0 | G7: =E7*D7 -> 90
B8: 46051 | C8: COMPRA | D8: 1.1593923 | E8: 82.94 | F8: 0 | G8: =E8*D8 -> 96.16
B9: 46087 | C9: COMPRA | D9: 1.0989234 | E9: 98.46 | F9: 0 | G9: =E9*D9 -> 108.2
G10: =E10*D10 -> 0 | I10: Qtde Comprada | J10: =SUMIFS(D3:D20,C3:C20,"COMPRA") -> 8.2276567
G11: =E11*D11 -> 0 | I11: Qtde Vendida | J11: =SUMIFS(D4:D21,C4:C21,"VENDA") -> 0
G12: =E12*D12 -> 0 | I12: Qtde em Carteira | J12: =J10-J11 -> 8.2276567
G13: =E13*D13 -> 0 | I13: Valor das Compras | J13: =SUMIFS(G4:G21,C4:C21,"COMPRA") -> 916.36
G14: =E14*D14 -> 0 | I14: Valor das Vendas | J14: =SUMIFS(E4:E21,C4:C21,"VENDA") -> 0
G15: =E15*D15 -> 0 | I15: Total de Taxas | J15: =SUM(F4:F21) -> 0
G16: =E16*D16 -> 0 | I16: Preço Médio | J16: =IF(J10<>0,((J13+J15)/J10),"") -> 111.37558
G17: =E17*D17 -> 0
G18: =E18*D18 -> 0
G19: =E19*D19 -> 0
G20: =E20*D20 -> 0
G21: =E21*D21 -> 0

Sheet META
B2: ID | C2: META | D2: Nome do Ativo | F2: =IFERROR(__xludf.DUMMYFUNCTION("IF(C2="""","""",GOOGLEFINANCE(C2,""Name""))"),"Meta Platforms Inc") -> Meta Platforms Inc
B3: Data | C3: Operação | D3: Qtde | E3: Valor unitário | F3: Taxas/Impostos | G3: Valor da operação | H3: Gráfico | K3: Dias graf
B4: 45848 | C4: COMPRA | D4: 0.33116238 | E4: 724.72 | F4: 0 | G4: =E4*D4 -> 240 | H4: =IFERROR(__xludf.DUMMYFUNCTION("IF(C2="""","""",SPARKLINE(GOOGLEFINANCE(C2,""price"",TODAY()-K4,TODAY())))"),"") | K4: 60
B5: 45922 | C5: COMPRA | D5: 0.41643423 | E5: 770.83 | F5: 0 | G5: =E5*D5 -> 321
B6: 45939 | C6: COMPRA | D6: 0.08473399 | E6: 719.9 | F6: 0 | G6: =E6*D6 -> 60.999999
B7: 46000 | C7: COMPRA | D7: 0.13712405 | E7: 656.34 | F7: 0 | G7: =E7*D7 -> 89.999999
B8: 46051 | C8: COMPRA | D8: 0.13156563 | E8: 730.89 | F8: 0 | G8: =E8*D8 -> 96.160003
B9: 46087 | C9: COMPRA | D9: 0.16757527 | E9: 645.68 | F9: 0 | G9: =E9*D9 -> 108.2
G10: =E10*D10 -> 0 | I10: Qtde Comprada | J10: =SUMIFS(D3:D20,C3:C20,"COMPRA") -> 1.2685955
G11: =E11*D11 -> 0 | I11: Qtde Vendida | J11: =SUMIFS(D4:D21,C4:C21,"VENDA") -> 0
G12: =E12*D12 -> 0 | I12: Qtde em Carteira | J12: =J10-J11 -> 1.2685955
G13: =E13*D13 -> 0 | I13: Valor das Compras | J13: =SUMIFS(G4:G21,C4:C21,"COMPRA") -> 916.36
G14: =E14*D14 -> 0 | I14: Valor das Vendas | J14: =SUMIFS(E4:E21,C4:C21,"VENDA") -> 0
G15: =E15*D15 -> 0 | I15: Total de Taxas | J15: =SUM(F4:F21) -> 0
G16: =E16*D16 -> 0 | I16: Preço Médio | J16: =IF(J10<>0,((J13+J15)/J10),"") -> 722.34212
G17: =E17*D17 -> 0
G18: =E18*D18 -> 0
G19: =E19*D19 -> 0
G20: =E20*D20 -> 0
G21: =E21*D21 -> 0

Sheet FAST
B2: ID | C2: FAST | D2: Nome do Ativo | F2: =IFERROR(__xludf.DUMMYFUNCTION("IF(C2="""","""",GOOGLEFINANCE(C2,""Name""))"),"Fastenal Co") -> Fastenal Co
B3: Data | C3: Operação | D3: Qtde | E3: Valor unitário | F3: Taxas/Impostos | G3: Valor da operação | H3: Gráfico | K3: Dias graf
B4: 44630 | C4: COMPRA | D4: 2 | E4: 27.15 | F4: 0 | G4: =E4*D4 -> 54.3 | H4: =IFERROR(__xludf.DUMMYFUNCTION("IF(C2="""","""",SPARKLINE(GOOGLEFINANCE(C2,""price"",TODAY()-K4,TODAY())))"),"") | K4: 30
B5: 44841 | C5: COMPRA | D5: 2 | E5: 23.15 | F5: 0 | G5: =E5*D5 -> 46.3
B6: 45246 | C6: COMPRA | D6: 2 | E6: 30.285 | F6: 0.3 | G6: =(E6*D6)+F6 -> 60.87
B7: 45505 | C7: COMPRA | D7: 1.8 | E7: 33.835 | F7: 0 | G7: =(E7*D7)+F7 -> 60.903
B8: 45551 | C8: COMPRA | D8: 0.86 | E8: 34.965 | F8: 0 | G8: =(E8*D8)+F8 -> 30.0699
B9: 45595 | C9: COMPRA | D9: 2.9444 | E9: 39.055 | F9: 0 | G9: =(E9*D9)+F9 -> 114.99354
B10: 45628 | C10: COMPRA | D10: 1.304 | E10: 41.405 | F10: 0 | G10: =(E10*D10)+F10 -> 53.99212 | I10: Qtde Comprada | J10: =SUMIFS(D4:D21,C4:C21,"COMPRA") -> 32.423903
B11: 45667 | C11: COMPRA | D11: 2.0372131 | E11: 36.815 | F11: 0 | G11: 75 | I11: Qtde Vendida | J11: =SUMIFS(D4:D21,C4:C21,"VENDA") -> 0
B12: 45758 | C12: COMPRA | D12: 1.2628451 | E12: 40.385 | F12: 0 | G12: 51 | I12: Qtde em Carteira | J12: =J10-J11 -> 32.423903
B13: 45848 | C13: COMPRA | D13: 5.4997718 | E13: 43.82 | F13: 0 | G13: =(E13*D13)+F13 -> 241 | I13: Valor das Compras | J13: =SUMIFS(G4:G21,C4:C21,"COMPRA") -> 1271.7886
B14: 45939 | C14: COMPRA | D14: 1.3020277 | E14: 46.85 | F14: 0 | G14: =(E14*D14)+F14 -> 61 | I14: Valor das Vendas | J14: =SUMIFS(E4:E21,C4:C21,"VENDA") -> 0
B15: 46000 | C15: COMPRA | D15: 2.2178413 | E15: 40.58 | F15: 0 | G15: =(E15*D15)+F15 -> 90 | I15: Total de Taxas | J15: =SUM(F4:F21) -> 0.3
B16: 46051 | C16: COMPRA | D16: 2.211083 | E16: 43.49 | F16: 0 | G16: =(E16*D16)+F16 -> 96.16 | I16: Preço Médio | J16: =IF(J10<>0,((J13+J15)/J10),"") -> 39.233049
B17: 46087 | C17: COMPRA | D17: 2.3455452 | E17: 46.13 | F17: 0 | G17: =(E17*D17)+F17 -> 108.2
B18: 46205 | C18: COMPRA | D18: 2.6391753 | E18: 48.5 | F18: 0 | G18: =(E18*D18)+F18 -> 128
G19: =(E19*D19)+F19 -> 0
G20: =(E20*D20)+F20 -> 0
G21: =(E21*D21)+F21 -> 0

Sheet KO
B2: ID | C2: KO | D2: Nome do Ativo | F2: =IFERROR(__xludf.DUMMYFUNCTION("IF(C2="""","""",GOOGLEFINANCE(C2,""Name""))"),"Coca-Cola Co") -> Coca-Cola Co
B3: Data | C3: Operação | D3: Qtde | E3: Valor unitário | F3: Taxas/Impostos | G3: Valor da operação | H3: Gráfico | K3: Dias graf
B4: 44630 | C4: COMPRA | D4: 1 | E4: 57.57 | F4: 0 | G4: =E4*D4 -> 57.57 | H4: =IFERROR(__xludf.DUMMYFUNCTION("IF(C2="""","""",SPARKLINE(GOOGLEFINANCE(C2,""price"",TODAY()-K4,TODAY())))"),"") | K4: 30
B5: 44841 | C5: COMPRA | D5: 1 | E5: 54.79 | F5: 0 | G5: =E5*D5 -> 54.79
B6: 45246 | C6: COMPRA | D6: 1.9888033 | E6: 57.16 | F6: 0 | G6: =E6*D6 -> 113.68
B7: 45595 | C7: COMPRA | D7: 1.7008134 | E7: 66.42 | F7: 0 | G7: =E7*D7 -> 112.96802
B8: 45628 | C8: COMPRA | D8: 0.85027586 | E8: 63.49 | F8: 0 | G8: =E8*D8 -> 53.984014
B9: 45667 | C9: COMPRA | D9: =G9/E9 -> 1.2135922 | E9: 61.8 | F9: 0 | G9: 75
B10: 45758 | C10: COMPRA | D10: =G10/E10 -> 0.71149554 | E10: 71.68 | F10: 0 | G10: 51 | I10: Qtde Comprada | J10: =SUMIFS(D4:D21,C4:C21,"COMPRA") -> 19.252848
B11: 45848 | C11: COMPRA | D11: 3.4234753 | E11: 69.52 | F11: 0 | G11: =E11*D11 -> 238 | I11: Qtde Vendida | J11: =SUMIFS(D4:D21,C4:C21,"VENDA") -> 0
B12: 45939 | C12: COMPRA | D12: 0.9141801 | E12: 66.77 | F12: 0 | G12: =E12*D12 -> 61.039805 | I12: Qtde em Carteira | J12: =J10-J11 -> 19.252848
B13: 45939 | C13: COMPRA | D13: 0.91442208 | E13: 66.77 | F13: 0 | G13: =E13*D13 -> 61.055962 | I13: Valor das Compras | J13: =SUMIFS(G4:G21,C4:C21,"COMPRA") -> 1301.5323
B14: 46000 | C14: COMPRA | D14: 1.2838802 | E14: 70.1 | F14: 0 | G14: =E14*D14 -> 90 | I14: Valor das Vendas | J14: =SUMIFS(E4:E21,C4:C21,"VENDA") -> 0
B15: 46051 | C15: COMPRA | D15: 1.3038644 | E15: 73.75 | F15: 0 | G15: =E15*D15 -> 96.16 | I15: Total de Taxas | J15: =SUM(F4:F21) -> 0
B16: 46087 | C16: COMPRA | D16: 1.4099542 | E16: 76.8 | F16: 0 | G16: =E16*D16 -> 108.28448 | I16: Preço Médio | J16: =IF(J10<>0,((J13+J15)/J10),"") -> 67.602064
B17: 46205 | C17: COMPRA | D17: 1.5380918 | E17: 83.22 | F17: 0 | G17: =E17*D17 -> 128
G18: =E18*D18 -> 0
G19: =E19*D19 -> 0
G20: =E20*D20 -> 0
G21: =E21*D21 -> 0

Sheet APH
B2: ID | C2: APH | D2: Nome do Ativo | F2: =IFERROR(__xludf.DUMMYFUNCTION("IF(C2="""","""",GOOGLEFINANCE(C2,""Name""))"),"Amphenol Corp") -> Amphenol Corp
B3: Data | C3: Operação | D3: Qtde | E3: Valor unitário | F3: Taxas/Impostos | G3: Valor da operação | H3: Gráfico | K3: Dias graf
B4: 44630 | C4: COMPRA | D4: 2 | E4: 18.035 | F4: 0 | G4: =E4*D4 -> 36.07 | H4: =IFERROR(__xludf.DUMMYFUNCTION("IF(C2="""","""",SPARKLINE(GOOGLEFINANCE(C2,""price"",TODAY()-K4,TODAY())))"),"") | K4: 30
B5: 45248 | C5: COMPRA | D5: 2 | E5: 22.505 | F5: 0 | G5: =E5*D5 -> 45.01
B6: 45505 | C6: COMPRA | D6: 2.001909 | E6: 31.46 | F6: 0 | G6: =E6*D6 -> 62.980057
B7: 45551 | C7: COMPRA | D7: 0.94652152 | E7: 31.685 | F7: 0 | G7: =E7*D7 -> 29.990534
B8: 45595 | C8: COMPRA | D8: 3.3046347 | E8: 34.195 | F8: 0 | G8: =E8*D8 -> 113.00198
B9: 45628 | C9: COMPRA | D9: 1.461101 | E9: 36.915 | F9: 0 | G9: =E9*D9 -> 53.936543
B10: 45667 | C10: COMPRA | D10: 2.050581 | E10: 36.575 | F10: 0 | G10: 75 | I10: Qtde Comprada | J10: =SUMIFS(D4:D21,C4:C21,"COMPRA") -> 27.644698
B11: 45758 | C11: COMPRA | D11: 1.5641773 | E11: 32.605 | F11: 0 | G11: 51 | I11: Qtde Vendida | J11: =SUMIFS(D4:D21,C4:C21,"VENDA") -> 0
B12: 45848 | C12: COMPRA | D12: 4.9175729 | E12: 49.195 | F12: 0 | G12: =E12*D12 -> 241.92 | I12: Qtde em Carteira | J12: =J10-J11 -> 27.644698
B13: 46000 | C13: COMPRA | D13: 1.2997328 | E13: 69.245 | F13: 0 | G13: =E13*D13 -> 90.000001 | I13: Valor das Compras | J13: =SUMIFS(G4:G21,C4:C21,"COMPRA") -> 1263.2948
B14: 46051 | C14: COMPRA | D14: 1.2780221 | E14: 75.03 | F14: 0 | G14: =E14*D14 -> 95.89 | I14: Valor das Vendas | J14: =SUMIFS(E4:E21,C4:C21,"VENDA") -> 0
B15: 46087 | C15: COMPRA | D15: 1.6236495 | E15: 66.64 | F15: 0 | G15: =E15*D15 -> 108.2 | I15: Total de Taxas | J15: =SUM(F4:F21) -> 0
B16: 46205 | C16: COMPRA | D16: 1.5725782 | E16: 81.335 | F16: 0 | G16: =E16*D16 -> 127.90564 | I16: Preço Médio | J16: =IF(J10<>0,((J13+J15)/J10),"") -> 45.697543
B17: 46209 | C17: COMPRA | D17: 1.6242179 | E17: 81.51 | F17: 0 | G17: =E17*D17 -> 132.39
G18: =E18*D18 -> 0
G19: =E19*D19 -> 0
G20: =E20*D20 -> 0
G21: =E21*D21 -> 0

Sheet EGIE3
B2: ID | C2: EGIE3 | D2: Nome do Ativo | F2: =IFERROR(__xludf.DUMMYFUNCTION("IF(C2="""","""",GOOGLEFINANCE(C2,""Name""))"),"Engie Brasil Energia SA") -> Engie Brasil Energia SA
B3: Data | C3: Operação | D3: Qtde | E3: Valor unitário | F3: Taxas/Impostos | G3: Valor da operação | H3: Gráfico | K3: Dias graf
B4: 44628 | C4: COMPRA | D4: 4.2 | E4: 27.93 | F4: 0 | G4: =E4*D4 -> 117.306 | H4: =IFERROR(__xludf.DUMMYFUNCTION("IF(C2="""","""",SPARKLINE(GOOGLEFINANCE(C2,""price"",TODAY()-K4,TODAY())))"),"") | K4: 60
B5: 44655 | C5: COMPRA | D5: 7 | E5: 31.26 | F5: 0 | G5: =E5*D5 -> 218.82
B6: 44841 | C6: COMPRA | D6: 4.2 | E6: 27.71 | F6: 0 | G6: =E6*D6 -> 116.382
B7: 44935 | C7: COMPRA | D7: 4.2 | E7: 27.11 | F7: 0 | G7: =E7*D7 -> 113.862
B8: 44999 | C8: COMPRA | D8: 11.2 | E8: 29.74 | F8: 0 | G8: =E8*D8 -> 333.088
B9: 45246 | C9: COMPRA | D9: 5.6 | E9: 31.04 | F9: 0 | G9: =E9*D9 -> 173.824
B10: 45300 | C10: COMPRA | D10: 4.2 | E10: 31.35 | F10: 0 | G10: =E10*D10 -> 131.67 | I10: Qtde Comprada | J10: =SUMIFS(D4:D28,C4:C28,"COMPRA") -> 161
B11: 45341 | C11: COMPRA | D11: 7 | E11: 29.44 | F11: 0 | G11: =E11*D11 -> 206.08 | I11: Qtde Vendida | J11: =SUMIFS(D4:D28,C4:C28,"VENDA") -> 0
B12: 45453 | C12: COMPRA | D12: 5.6 | E12: 31.02 | F12: 0 | G12: =E12*D12 -> 173.712 | I12: Qtde em Carteira | J12: =J10-J11 -> 161
B13: 45505 | C13: COMPRA | D13: 4.2 | E13: 31.71 | F13: 0 | G13: =E13*D13 -> 133.182 | I13: Valor das Compras | J13: =SUMIFS(G4:G28,C4:C28,"COMPRA") -> 4814.718
B14: 45551 | C14: COMPRA | D14: 4.2 | E14: 31.64 | F14: 0 | G14: =E14*D14 -> 132.888 | I14: Valor das Vendas | J14: =SUMIFS(E4:E28,C4:C28,"VENDA") -> 0
B15: 45595 | C15: COMPRA | D15: 21 | E15: 29.44 | F15: 0 | G15: =E15*D15 -> 618.24 | I15: Total de Taxas | J15: =SUM(F4:F28) -> 0
B16: 45628 | C16: COMPRA | D16: 5.6 | E16: 26.71 | F16: 0 | G16: =E16*D16 -> 149.576 | I16: Preço Médio | J16: =IF(J10<>0,((J13+J15)/J10),"") -> 29.905081
B17: 45667 | C17: COMPRA | D17: 8.4 | E17: 25.16 | F17: 0 | G17: =E17*D17 -> 211.344
B18: 45758 | C18: COMPRA | D18: 4.2 | E18: 28.22 | F18: 0 | G18: =E18*D18 -> 118.524
B19: 45848 | C19: COMPRA | D19: 8.4 | E19: 30 | F19: 0 | G19: =E19*D19 -> 252
B20: 45922 | C20: COMPRA | D20: 8.4 | E20: 29.74 | F20: 0 | G20: =E20*D20 -> 249.816
B21: 45939 | C21: COMPRA | D21: 8.4 | E21: 28.46 | F21: 0 | G21: =E21*D21 -> 239.064
B22: 46000 | C22: COMPRA | D22: 7 | E22: 30.4 | F22: 0 | G22: =E22*D22 -> 212.8
B23: 46051 | C23: COMPRA | D23: 8 | E23: 33.38 | F23: 0 | G23: =E23*D23 -> 267.04
B24: 46087 | C24: COMPRA | D24: 10 | E24: 31.85 | F24: 0 | G24: =E24*D24 -> 318.5
B25: 46205 | C25: COMPRA | D25: 10 | E25: 32.7 | F25: 0 | G25: =E25*D25 -> 327

Sheet KNRI11
B2: ID | C2: KNRI11 | D2: Nome do Ativo | F2: =IFERROR(__xludf.DUMMYFUNCTION("IF(C2="""","""",GOOGLEFINANCE(C2,""Name""))"),"Kinea Renda Imobiliaria FII") -> Kinea Renda Imobiliaria FII
B3: Data | C3: Operação | D3: Qtde | E3: Valor unitário | F3: Taxas/Impostos | G3: Valor da operação | H3: Gráfico | K3: Dias graf
B4: 44628 | C4: COMPRA | D4: 1 | E4: 130.38 | F4: 0 | G4: =E4*D4 -> 130.38 | H4: =IFERROR(__xludf.DUMMYFUNCTION("IF(C2="""","""",SPARKLINE(GOOGLEFINANCE(C2,""price"",TODAY()-K4,TODAY())))"),"") | K4: 30
B5: 44743 | C5: COMPRA | D5: 1 | E5: 130.59 | F5: 0 | G5: =E5*D5 -> 130.59
B6: 44841 | C6: COMPRA | D6: 1 | E6: 152.84 | F6: 0 | G6: =E6*D6 -> 152.84
B7: 44935 | C7: COMPRA | D7: 1 | E7: 138.69 | F7: 0 | G7: =E7*D7 -> 138.69
B8: 44999 | C8: COMPRA | D8: 2 | E8: 137.51 | F8: 0 | G8: =E8*D8 -> 275.02
B9: 45300 | C9: COMPRA | D9: 1 | E9: 164.38 | F9: 0 | G9: =E9*D9 -> 164.38
B10: 45341 | C10: COMPRA | D10: 2 | E10: 136.65 | F10: 0 | G10: =E10*D10 -> 273.3 | I10: Qtde Comprada | J10: =SUMIFS(D4:D25,C4:C25,"COMPRA") -> 30
B11: 45426 | C11: COMPRA | D11: 1 | E11: 160.7 | F11: 0 | G11: =E11*D11 -> 160.7 | I11: Qtde Vendida | J11: =SUMIFS(D4:D25,C4:C25,"VENDA") -> 0
B12: 45453 | C12: COMPRA | D12: 1 | E12: 157.84 | F12: 0 | G12: =E12*D12 -> 157.84 | I12: Qtde em Carteira | J12: =J10-J11 -> 30
B13: 45505 | C13: COMPRA | D13: 1 | E13: 154.6 | F13: 0 | G13: =E13*D13 -> 154.6 | I13: Valor das Compras | J13: =SUMIFS(G4:G25,C4:C25,"COMPRA") -> 4371.3
B14: 45551 | C14: COMPRA | D14: 1 | E14: 148.29 | F14: 0 | G14: =E14*D14 -> 148.29 | I14: Valor das Vendas | J14: =SUMIFS(E4:E25,C4:C25,"VENDA") -> 0
B15: 45595 | C15: COMPRA | D15: 4 | E15: 138.55 | F15: 0 | G15: =E15*D15 -> 554.2 | I15: Total de Taxas | J15: =SUM(F4:F25) -> 0
B16: 45628 | C16: COMPRA | D16: 1 | E16: 131.2 | F16: 0 | G16: =E16*D16 -> 131.2 | I16: Preço Médio | J16: =IF(J10<>0,((J13+J15)/J10),"") -> 145.71
B17: 45667 | C17: COMPRA | D17: 1 | E17: 133.74 | F17: 0 | G17: =E17*D17 -> 133.74
B18: 45758 | C18: COMPRA | D18: 1 | E18: 134.77 | F18: 0 | G18: =E18*D18 -> 134.77
B19: 45848 | C19: COMPRA | D19: 2 | E19: 143.83 | F19: 0 | G19: =E19*D19 -> 287.66
B20: 45922 | C20: COMPRA | D20: 1 | E20: 147.79 | F20: 0 | G20: =E20*D20 -> 147.79
B21: 45939 | C21: COMPRA | D21: 2 | E21: 144.43 | F21: 0 | G21: =E21*D21 -> 288.86
B22: 46051 | C22: COMPRA | D22: 1 | E22: 162.01 | F22: 0 | G22: =E22*D22 -> 162.01
B23: 46087 | C23: COMPRA | D23: 2 | E23: 167.1 | F23: 0 | G23: =E23*D23 -> 334.2
B24: 46205 | C24: COMPRA | D24: 2 | E24: 155.12 | F24: 0 | G24: =E24*D24 -> 310.24

Sheet HGRU11
B2: ID | C2: HGRU11 | D2: Nome do Ativo | F2: =IFERROR(__xludf.DUMMYFUNCTION("IF(C2="""","""",GOOGLEFINANCE(C2,""Name""))"),"Patria Renda Urbana FII RL Unica") -> Patria Renda Urbana FII RL Unica
B3: Data | C3: Operação | D3: Qtde | E3: Valor unitário | F3: Taxas/Impostos | G3: Valor da operação | H3: Gráfico | K3: Dias graf
B4: 44628 | C4: COMPRA | D4: 1 | E4: 110.99 | F4: 0 | G4: =E4*D4 -> 110.99 | H4: =IFERROR(__xludf.DUMMYFUNCTION("IF(C2="""","""",SPARKLINE(GOOGLEFINANCE(C2,""price"",TODAY()-K4,TODAY())))"),"") | K4: 30
B5: 44655 | C5: COMPRA | D5: 1 | E5: 113.79 | F5: 0 | G5: =E5*D5 -> 113.79
B6: 44841 | C6: COMPRA | D6: 1 | E6: 126.14 | F6: 0 | G6: =E6*D6 -> 126.14
B7: 44935 | C7: COMPRA | D7: 1 | E7: 117.35 | F7: 0 | G7: =E7*D7 -> 117.35
B8: 44999 | C8: COMPRA | D8: 3 | E8: 115.58 | F8: 0 | G8: =E8*D8 -> 346.74
B9: 45246 | C9: COMPRA | D9: 1 | E9: 130.49 | F9: 0 | G9: =E9*D9 -> 130.49
B10: 45300 | C10: COMPRA | D10: 3 | E10: 137.78 | F10: 0 | G10: =E10*D10 -> 413.34 | I10: Qtde Comprada | J10: =SUMIFS(D4:D26,C4:C26,"COMPRA") -> 39
B11: 45426 | C11: COMPRA | D11: 1 | E11: 129.65 | F11: 0 | G11: =E11*D11 -> 129.65 | I11: Qtde Vendida | J11: =SUMIFS(D4:D26,C4:C26,"VENDA") -> 0
B12: 45453 | C12: COMPRA | D12: 1 | E12: 127.92 | F12: 0 | G12: =E12*D12 -> 127.92 | I12: Qtde em Carteira | J12: =J10-J11 -> 39
B13: 45505 | C13: COMPRA | D13: 1 | E13: 126.77 | F13: 0 | G13: =E13*D13 -> 126.77 | I13: Valor das Compras | J13: =SUMIFS(G4:G26,C4:C26,"COMPRA") -> 4852.01
B14: 45551 | C14: COMPRA | D14: 1 | E14: 124.91 | F14: 0 | G14: =E14*D14 -> 124.91 | I14: Valor das Vendas | J14: =SUMIFS(E4:E26,C4:C26,"VENDA") -> 0
B15: 45595 | C15: COMPRA | D15: 5 | E15: 122.65 | F15: 0 | G15: =E15*D15 -> 613.25 | I15: Total de Taxas | J15: =SUM(F4:F26) -> 0
B16: 45628 | C16: COMPRA | D16: 1 | E16: 114.75 | F16: 0 | G16: =E16*D16 -> 114.75 | I16: Preço Médio | J16: =IF(J10<>0,((J13+J15)/J10),"") -> 124.41051
B17: 45667 | C17: COMPRA | D17: 2 | E17: 114.42 | F17: 0 | G17: =E17*D17 -> 228.84
B18: 45758 | C18: COMPRA | D18: 1 | E18: 115.11 | F18: 0 | G18: =E18*D18 -> 115.11
B19: 45848 | C19: COMPRA | D19: 2 | E19: 124.32 | F19: 0 | G19: =E19*D19 -> 248.64
B20: 45922 | C20: COMPRA | D20: 2 | E20: 126.84 | F20: 0 | G20: =E20*D20 -> 253.68
B21: 45939 | C21: COMPRA | D21: 2 | E21: 125.91 | F21: 0 | G21: =E21*D21 -> 251.82
B22: 46000 | C22: COMPRA | D22: 2 | E22: 127.61 | F22: 0 | G22: =E22*D22 -> 255.22
B23: 46051 | C23: COMPRA | D23: 2 | E23: 127.12 | F23: 0 | G23: =E23*D23 -> 254.24
B24: 46087 | C24: COMPRA | D24: 2 | E24: 129.86 | F24: 0 | G24: =E24*D24 -> 259.72
B25: 46205 | C25: COMPRA | D25: 3 | E25: 129.55 | F25: 0 | G25: =E25*D25 -> 388.65

Sheet HGLG11
B2: ID | C2: HGLG11 | D2: Nome do Ativo | F2: =IFERROR(__xludf.DUMMYFUNCTION("IF(C2="""","""",GOOGLEFINANCE(C2,""Name""))"),"Patria Log FII RL") -> Patria Log FII RL
B3: Data | C3: Operação | D3: Qtde | E3: Valor unitário | F3: Taxas/Impostos | G3: Valor da operação | H3: Gráfico | K3: Dias graf
B4: 44628 | C4: COMPRA | D4: 1 | E4: 161.5 | F4: 0 | G4: =E4*D4 -> 161.5 | H4: =IFERROR(__xludf.DUMMYFUNCTION("IF(C2="""","""",SPARKLINE(GOOGLEFINANCE(C2,""price"",TODAY()-K4,TODAY())))"),"") | K4: 30
B5: 44743 | C5: COMPRA | D5: 1 | E5: 161.15 | F5: 0 | G5: =E5*D5 -> 161.15
B6: 44841 | C6: COMPRA | D6: 1 | E6: 168.68 | F6: 0 | G6: =E6*D6 -> 168.68
B7: 44999 | C7: COMPRA | D7: 2 | E7: 160.2 | F7: 0 | G7: =E7*D7 -> 320.4
B8: 45246 | C8: COMPRA | D8: 1 | E8: 160.01 | F8: 0 | G8: =E8*D8 -> 160.01
B9: 45300 | C9: COMPRA | D9: 1 | E9: 162.1 | F9: 0 | G9: =E9*D9 -> 162.1
B10: 45341 | C10: COMPRA | D10: 1 | E10: 165.6 | F10: 0 | G10: =E10*D10 -> 165.6 | I10: Qtde Comprada | J10: =SUMIFS(D4:D26,C4:C26,"COMPRA") -> 28
B11: 45426 | C11: COMPRA | D11: 1 | E11: 161.59 | F11: 0 | G11: =E11*D11 -> 161.59 | I11: Qtde Vendida | J11: =SUMIFS(D4:D26,C4:C26,"VENDA") -> 0
B12: 45453 | C12: COMPRA | D12: 1 | E12: 160 | F12: 0 | G12: =E12*D12 -> 160 | I12: Qtde em Carteira | J12: =J10-J11 -> 28
B13: 45505 | C13: COMPRA | D13: 1 | E13: 159.41 | F13: 0 | G13: =E13*D13 -> 159.41 | I13: Valor das Compras | J13: =SUMIFS(G4:G26,C4:C26,"COMPRA") -> 4422.38
B14: 45551 | C14: COMPRA | D14: 1 | E14: 160.23 | F14: 0 | G14: =E14*D14 -> 160.23 | I14: Valor das Vendas | J14: =SUMIFS(E4:E26,C4:C26,"VENDA") -> 0
B15: 45595 | C15: COMPRA | D15: 4 | E15: 155.54 | F15: 0 | G15: =E15*D15 -> 622.16 | I15: Total de Taxas | J15: =SUM(F4:F26) -> 0
B16: 45628 | C16: COMPRA | D16: 1 | E16: 150.07 | F16: 0 | G16: =E16*D16 -> 150.07 | I16: Preço Médio | J16: =IF(J10<>0,((J13+J15)/J10),"") -> 157.94214
B17: 45667 | C17: COMPRA | D17: 1 | E17: 151.01 | F17: 0 | G17: =E17*D17 -> 151.01
B18: 45758 | C18: COMPRA | D18: 1 | E18: 152.33 | F18: 0 | G18: =E18*D18 -> 152.33
B19: 45848 | C19: COMPRA | D19: 1 | E19: 154.98 | F19: 0 | G19: =E19*D19 -> 154.98
B20: 45922 | C20: COMPRA | D20: 1 | E20: 159.17 | F20: 0 | G20: =E20*D20 -> 159.17
B21: 45939 | C21: COMPRA | D21: 1 | E21: 159.72 | F21: 0 | G21: =E21*D21 -> 159.72
B22: 46000 | C22: COMPRA | D22: 1 | E22: 159.24 | F22: 0 | G22: =E22*D22 -> 159.24
B23: 46051 | C23: COMPRA | D23: 1 | E23: 157.63 | F23: 0 | G23: =E23*D23 -> 157.63
B24: 46087 | C24: COMPRA | D24: 2 | E24: 158.42 | F24: 0 | G24: =E24*D24 -> 316.84
B25: 02/07/1016 | C25: COMPRA | D25: 2 | E25: 149.28 | F25: 0 | G25: =E25*D25 -> 298.56

Sheet VISC11
B2: ID | C2: VISC11 | D2: Nome do Ativo | F2: =IFERROR(__xludf.DUMMYFUNCTION("IF(C2="""","""",GOOGLEFINANCE(C2,""Name""))"),"Vinci Shopping Centers FI Imobiliario") -> Vinci Shopping Centers FI Imobiliario
B3: Data | C3: Operação | D3: Qtde | E3: Valor unitário | F3: Taxas/Impostos | G3: Valor da operação | H3: Gráfico | K3: Dias graf
B4: 44628 | C4: COMPRA | D4: 1 | E4: 98.73 | F4: 0 | G4: =E4*D4 -> 98.73 | H4: =IFERROR(__xludf.DUMMYFUNCTION("IF(C2="""","""",SPARKLINE(GOOGLEFINANCE(C2,""price"",TODAY()-K4,TODAY())))"),"") | K4: 30
B5: 44655 | C5: COMPRA | D5: 1 | E5: 100.33 | F5: 0 | G5: =E5*D5 -> 100.33
B6: 44841 | C6: COMPRA | D6: 2 | E6: 112.6 | F6: 0 | G6: =E6*D6 -> 225.2
B7: 44935 | C7: COMPRA | D7: 1 | E7: 104.89 | F7: 0 | G7: =E7*D7 -> 104.89
B8: 44999 | C8: COMPRA | D8: 3 | E8: 102.68 | F8: 0 | G8: =E8*D8 -> 308.04
B9: 45246 | C9: COMPRA | D9: 1 | E9: 119.75 | F9: 0 | G9: =E9*D9 -> 119.75
B10: 45300 | C10: COMPRA | D10: 1 | E10: 120.39 | F10: 0 | G10: =E10*D10 -> 120.39 | I10: Qtde Comprada | J10: =SUMIFS(D4:D27,C4:C27,"COMPRA") -> 42
B11: 45341 | C11: COMPRA | D11: 2 | E11: 121.57 | F11: 0 | G11: =E11*D11 -> 243.14 | I11: Qtde Vendida | J11: =SUMIFS(D4:D27,C4:C27,"VENDA") -> 0
B12: 45426 | C12: COMPRA | D12: 1 | E12: 120.64 | F12: 0 | G12: =E12*D12 -> 120.64 | I12: Qtde em Carteira | J12: =J10-J11 -> 42
B13: 45453 | C13: COMPRA | D13: 1 | E13: 115.29 | F13: 0 | G13: =E13*D13 -> 115.29 | I13: Valor das Compras | J13: =SUMIFS(G4:G27,C4:C27,"COMPRA") -> 4520.49
B14: 45505 | C14: COMPRA | D14: 1 | E14: 112.37 | F14: 0 | G14: =E14*D14 -> 112.37 | I14: Valor das Vendas | J14: =SUMIFS(E4:E27,C4:C27,"VENDA") -> 0
B15: 45551 | C15: COMPRA | D15: 1 | E15: 108.95 | F15: 0 | G15: =E15*D15 -> 108.95 | I15: Total de Taxas | J15: =SUM(F4:F27) -> 0
B16: 45595 | C16: COMPRA | D16: 6 | E16: 104.69 | F16: 0 | G16: =E16*D16 -> 628.14 | I16: Preço Médio | J16: =IF(J10<>0,((J13+J15)/J10),"") -> 107.63071
B17: 45628 | C17: COMPRA | D17: 1 | E17: 96.76 | F17: 0 | G17: =E17*D17 -> 96.76
B18: 45667 | C18: COMPRA | D18: 2 | E18: 93.81 | F18: 0 | G18: =E18*D18 -> 187.62
B19: 45758 | C19: COMPRA | D19: 1 | E19: 99.06 | F19: 0 | G19: =E19*D19 -> 99.06
B20: 45848 | C20: COMPRA | D20: 2 | E20: 103.64 | F20: 0 | G20: =E20*D20 -> 207.28
B21: 45922 | C21: COMPRA | D21: 2 | E21: 108.33 | F21: 0 | G21: =E21*D21 -> 216.66
B22: 45939 | C22: COMPRA | D22: 2 | E22: 109.03 | F22: 0 | G22: =E22*D22 -> 218.06
B23: 46000 | C23: COMPRA | D23: 2 | E23: 110.83 | F23: 0 | G23: =E23*D23 -> 221.66
B24: 46051 | C24: COMPRA | D24: 2 | E24: 108.94 | F24: 0 | G24: =E24*D24 -> 217.88
B25: 46087 | C25: COMPRA | D25: 3 | E25: 111.9 | F25: 0 | G25: =E25*D25 -> 335.7
B26: 46205 | C26: COMPRA | D26: 3 | E26: 104.65 | F26: 0 | G26: =E26*D26 -> 313.95

Sheet ITUB3
B2: ID | C2: ITUB3 | D2: Nome do Ativo | F2: =IFERROR(__xludf.DUMMYFUNCTION("IF(C2="""","""",GOOGLEFINANCE(C2,""Name""))"),"Itau Unibanco Holding Cedear") -> Itau Unibanco Holding Cedear
B3: Data | C3: Operação | D3: Qtde | E3: Valor unitário | F3: Taxas/Impostos | G3: Valor da operação | H3: Gráfico | K3: Dias graf
B4: 44628 | C4: COMPRA | D4: 5 | E4: 20.54 | F4: 0 | G4: =E4*D4 -> 102.7 | H4: =IFERROR(__xludf.DUMMYFUNCTION("IF(C2="""","""",SPARKLINE(GOOGLEFINANCE(C2,""price"",TODAY()-K4,TODAY())))"),"") | K4: 30
B5: 44655 | C5: COMPRA | D5: 5 | E5: 23.44 | F5: 0 | G5: =E5*D5 -> 117.2
B6: 44743 | C6: COMPRA | D6: 3 | E6: 19.7 | F6: 0 | G6: =E6*D6 -> 59.1
B7: 44841 | C7: COMPRA | D7: 5 | E7: 22.23 | F7: 0 | G7: =E7*D7 -> 111.15
B8: 44935 | C8: COMPRA | D8: 5 | E8: 22.11 | F8: 0 | G8: =E8*D8 -> 110.55
B9: 44999 | C9: COMPRA | D9: 15 | E9: 20.59 | F9: 0 | G9: =E9*D9 -> 308.85
B10: 45246 | C10: COMPRA | D10: 7 | E10: 25.59 | F10: 0 | G10: =E10*D10 -> 179.13 | I10: Qtde Comprada | J10: =SUMIFS(D4:D25,C4:C25,"COMPRA") -> 142
B11: 45300 | C11: COMPRA | D11: 5 | E11: 27.97 | F11: 0 | G11: =E11*D11 -> 139.85 | I11: Qtde Vendida | J11: =SUMIFS(D4:D25,C4:C25,"VENDA") -> 0
B12: 45341 | C12: COMPRA | D12: 8 | E12: 29.9 | F12: 0 | G12: =E12*D12 -> 239.2 | I12: Qtde em Carteira | J12: =J10-J11 -> 142
B13: 45453 | C13: COMPRA | D13: 5 | E13: 27.02 | F13: 0 | G13: =E13*D13 -> 135.1 | I13: Valor das Compras | J13: =SUMIFS(G4:G25,C4:C25,"COMPRA") -> 4147.78
B14: 45505 | C14: COMPRA | D14: 4 | E14: 28.88 | F14: 0 | G14: =E14*D14 -> 115.52 | I14: Valor das Vendas | J14: =SUMIFS(E4:E25,C4:C25,"VENDA") -> 0
B15: 45595 | C15: COMPRA | D15: 20 | E15: 30.41 | F15: 0 | G15: =E15*D15 -> 608.2 | I15: Total de Taxas | J15: =SUM(F4:F25) -> 0
B16: 45628 | C16: COMPRA | D16: 5 | E16: 28.19 | F16: 0 | G16: =E16*D16 -> 140.95 | I16: Preço Médio | J16: =IF(J10<>0,((J13+J15)/J10),"") -> 29.209718
B17: 45667 | C17: COMPRA | D17: 8 | E17: 27.25 | F17: 0 | G17: =E17*D17 -> 218
B18: 45758 | C18: COMPRA | D18: 5 | E18: 28.27 | F18: 0 | G18: =E18*D18 -> 141.35
B19: 45848 | C19: COMPRA | D19: 8 | E19: 31.72 | F19: 0 | G19: =E19*D19 -> 253.76
B20: 45922 | C20: COMPRA | D20: 8 | E20: 34.14 | F20: 0 | G20: =E20*D20 -> 273.12
B21: 46051 | C21: COMPRA | D21: 6 | E21: 42.66 | F21: 0 | G21: =E21*D21 -> 255.96
B22: 46087 | C22: COMPRA | D22: 8 | E22: 40.78 | F22: 0 | G22: =E22*D22 -> 326.24
B23: 46205 | C23: COMPRA | D23: 7 | E23: 44.55 | F23: 0 | G23: =E23*D23 -> 311.85

Sheet WEGE3
B2: ID | C2: WEGE3 | D2: Nome do Ativo | F2: =IFERROR(__xludf.DUMMYFUNCTION("IF(C2="""","""",GOOGLEFINANCE(C2,""Name""))"),"Weg Cedear") -> Weg Cedear
B3: Data | C3: Operação | D3: Qtde | E3: Valor unitário | F3: Taxas/Impostos | G3: Valor da operação | H3: Gráfico | K3: Dias graf
B4: 44628 | C4: COMPRA | D4: 4 | E4: 31.72 | F4: 0 | G4: =E4*D4 -> 126.88 | H4: =IFERROR(__xludf.DUMMYFUNCTION("IF(C2="""","""",SPARKLINE(GOOGLEFINANCE(C2,""price"",TODAY()-K4,TODAY())))"),"") | K4: 60
B5: 44655 | C5: COMPRA | D5: 4 | E5: 34.8 | F5: 0 | G5: =E5*D5 -> 139.2
B6: 44841 | C6: COMPRA | D6: 4 | E6: 33.54 | F6: 0 | G6: =E6*D6 -> 134.16
B7: 44999 | C7: COMPRA | D7: 8 | E7: 40.17 | F7: 0 | G7: =E7*D7 -> 321.36
B8: 45246 | C8: COMPRA | D8: 6 | E8: 33.53 | F8: 0 | G8: =E8*D8 -> 201.18
B9: 45246 | C9: COMPRA | D9: 2 | E9: 33.54 | F9: 0 | G9: =E9*D9 -> 67.08
B10: 45246 | C10: COMPRA | D10: 2 | E10: 33.47 | F10: 0 | G10: =E10*D10 -> 66.94 | I10: Qtde Comprada | J10: =SUMIFS(D4:D29,C4:C29,"COMPRA") -> 126
B11: 45300 | C11: COMPRA | D11: 3 | E11: 35.83 | F11: 0 | G11: =E11*D11 -> 107.49 | I11: Qtde Vendida | J11: =SUMIFS(D4:D29,C4:C29,"VENDA") -> 0
B12: 45341 | C12: COMPRA | D12: 7 | E12: 33.44 | F12: 0 | G12: =E12*D12 -> 234.08 | I12: Qtde em Carteira | J12: =J10-J11 -> 126
B13: 45341 | C13: COMPRA | D13: 3 | E13: 39.54 | F13: 0 | G13: =E13*D13 -> 118.62 | I13: Valor das Compras | J13: =SUMIFS(G4:G29,C4:C29,"COMPRA") -> 5295.45
B14: 45453 | C14: COMPRA | D14: 4 | E14: 37.95 | F14: 0 | G14: =E14*D14 -> 151.8 | I14: Valor das Vendas | J14: =SUMIFS(E4:E29,C4:C29,"VENDA") -> 0
B15: 45505 | C15: COMPRA | D15: 2 | E15: 51.56 | F15: 0 | G15: =E15*D15 -> 103.12 | I15: Total de Taxas | J15: =SUM(F4:F29) -> 0
B16: 45595 | C16: COMPRA | D16: 12 | E16: 53.78 | F16: 0 | G16: =E16*D16 -> 645.36 | I16: Preço Médio | J16: =IF(J10<>0,((J13+J15)/J10),"") -> 42.027381
B17: 45628 | C17: COMPRA | D17: 5 | E17: 53.9 | F17: 0 | G17: =E17*D17 -> 269.5
B18: 45667 | C18: COMPRA | D18: 4 | E18: 53.8 | F18: 0 | G18: =E18*D18 -> 215.2
B19: 45758 | C19: COMPRA | D19: 5 | E19: 45.18 | F19: 0 | G19: =E19*D19 -> 225.9
B20: 45848 | C20: COMPRA | D20: 8 | E20: 39.83 | F20: 0 | G20: =E20*D20 -> 318.64
B21: 45922 | C21: COMPRA | D21: 7 | E21: 36.67 | F21: 0 | G21: =E21*D21 -> 256.69
B22: 45939 | C22: COMPRA | D22: 12 | E22: 36.95 | F22: 0 | G22: =E22*D22 -> 443.4
B23: 46000 | C23: COMPRA | D23: 5 | E23: 47.38 | F23: 0 | G23: =E23*D23 -> 236.9
B24: 46051 | C24: COMPRA | D24: 5 | E24: 52.33 | F24: 0 | G24: =E24*D24 -> 261.65
B25: 46087 | C25: COMPRA | D25: 7 | E25: 46.63 | F25: 0 | G25: =E25*D25 -> 326.41
B26: 46205 | C26: COMPRA | D26: 7 | E26: 46.27 | F26: 0 | G26: =E26*D26 -> 323.89
G29: =E29*D29 -> 0

Sheet TAEE3
B2: ID | C2: TAEE3 | D2: Nome do Ativo | F2: =IFERROR(__xludf.DUMMYFUNCTION("IF(C2="""","""",GOOGLEFINANCE(C2,""Name""))"),"Transmissora Alianca de Enrga Eltrca S/A") -> Transmissora Alianca de Enrga Eltrca S/A
B3: Data | C3: Operação | D3: Qtde | E3: Valor unitário | F3: Taxas/Impostos | G3: Valor da operação | H3: Gráfico | K3: Dias graf
B4: 44628 | C4: COMPRA | D4: 9 | E4: 13.36 | F4: 0 | G4: =E4*D4 -> 120.24 | H4: =IFERROR(__xludf.DUMMYFUNCTION("IF(C2="""","""",SPARKLINE(GOOGLEFINANCE(C2,""price"",TODAY()-K4,TODAY())))"),"") | K4: 30
B5: 44743 | C5: COMPRA | D5: 14 | E5: 13.19 | F5: 0 | G5: =E5*D5 -> 184.66
B6: 44841 | C6: COMPRA | D6: 9 | E6: 13.26 | F6: 0 | G6: =E6*D6 -> 119.34
B7: 44935 | C7: COMPRA | D7: 8 | E7: 11.98 | F7: 0 | G7: =E7*D7 -> 95.84
B8: 44999 | C8: COMPRA | D8: 25 | E8: 12.23 | F8: 0 | G8: =E8*D8 -> 305.75
B9: 45246 | C9: COMPRA | D9: 16 | E9: 12.08 | F9: 0 | G9: =E9*D9 -> 193.28
B10: 45300 | C10: COMPRA | D10: 10 | E10: 12.38 | F10: 0 | G10: =E10*D10 -> 123.8 | I10: Qtde Comprada | J10: =SUMIFS(D4:D30,C4:C30,"COMPRA") -> 406
B11: 45341 | C11: COMPRA | D11: 20 | E11: 11.72 | F11: 0 | G11: =E11*D11 -> 234.4 | I11: Qtde Vendida | J11: =SUMIFS(D4:D30,C4:C30,"VENDA") -> 0
B12: 45426 | C12: COMPRA | D12: 8 | E12: 11.55 | F12: 0 | G12: =E12*D12 -> 92.4 | I12: Qtde em Carteira | J12: =J10-J11 -> 406
B13: 45453 | C13: COMPRA | D13: 14 | E13: 11.16 | F13: 0 | G13: =E13*D13 -> 156.24 | I13: Valor das Compras | J13: =SUMIFS(G4:G30,C4:C30,"COMPRA") -> 4955.09
B14: 45505 | C14: COMPRA | D14: 11 | E14: 11.32 | F14: 0 | G14: =E14*D14 -> 124.52 | I14: Valor das Vendas | J14: =SUMIFS(E4:E30,C4:C30,"VENDA") -> 0
B15: 45551 | C15: COMPRA | D15: 13 | E15: 11.72 | F15: 0 | G15: =E15*D15 -> 152.36 | I15: Total de Taxas | J15: =SUM(F4:F30) -> 0
B16: 45595 | C16: COMPRA | D16: 53 | E16: 11.48 | F16: 0 | G16: =E16*D16 -> 608.44 | I16: Preço Médio | J16: =IF(J10<>0,((J13+J15)/J10),"") -> 12.204655
B17: 45628 | C17: COMPRA | D17: 14 | E17: 11.28 | F17: 0 | G17: =E17*D17 -> 157.92
B18: 45667 | C18: COMPRA | D18: 19 | E18: 10.89 | F18: 0 | G18: =E18*D18 -> 206.91
B19: 45758 | C19: COMPRA | D19: 12 | E19: 11.32 | F19: 0 | G19: =E19*D19 -> 135.84
B20: 45848 | C20: COMPRA | D20: 24 | E20: 11.32 | F20: 0 | G20: =E20*D20 -> 271.68
B21: 45922 | C21: COMPRA | D21: 22 | E21: 11.83 | F21: 0 | G21: =E21*D21 -> 260.26
B22: 45939 | C22: COMPRA | D22: 19 | E22: 11.97 | F22: 0 | G22: =E22*D22 -> 227.43
B23: 46000 | C23: COMPRA | D23: 17 | E23: 13.65 | F23: 0 | G23: =E23*D23 -> 232.05
B24: 46051 | C24: COMPRA | D24: 19 | E24: 14.03 | F24: 0 | G24: =E24*D24 -> 266.57
B25: 46087 | C25: COMPRA | D25: 24 | E25: 14.01 | F25: 0 | G25: =E25*D25 -> 336.24
B26: 46205 | C26: COMPRA | D26: 26 | E26: 13.42 | F26: 0 | G26: =E26*D26 -> 348.92

Sheet PSSA3
B2: ID | C2: PSSA3 | D2: Nome do Ativo | F2: =IFERROR(__xludf.DUMMYFUNCTION("IF(C2="""","""",GOOGLEFINANCE(C2,""Name""))"),"Porto Seguro SA") -> Porto Seguro SA
B3: Data | C3: Operação | D3: Qtde | E3: Valor unitário | F3: Taxas/Impostos | G3: Valor da operação | H3: Gráfico | K3: Dias graf
B4: 44628 | C4: COMPRA | D4: 6 | E4: 19.68 | F4: 0 | G4: =E4*D4 -> 118.08 | H4: =IFERROR(__xludf.DUMMYFUNCTION("IF(C2="""","""",SPARKLINE(GOOGLEFINANCE(C2,""price"",TODAY()-K4,TODAY())))"),"") | K4: 30
B5: 44655 | C5: COMPRA | D5: 4 | E5: 20.86 | F5: 0 | G5: =E5*D5 -> 83.44
B6: 44743 | C6: COMPRA | D6: 5 | E6: 18.04 | F6: 0 | G6: =E6*D6 -> 90.2
B7: 44841 | C7: COMPRA | D7: 5 | E7: 21.27 | F7: 0 | G7: =E7*D7 -> 106.35
B8: 44999 | C8: COMPRA | D8: 12 | E8: 24.89 | F8: 0 | G8: =E8*D8 -> 298.68
B9: 45246 | C9: COMPRA | D9: 7 | E9: 28.22 | F9: 0 | G9: =E9*D9 -> 197.54
B10: 45300 | C10: COMPRA | D10: 5 | E10: 28.54 | F10: 0 | G10: =E10*D10 -> 142.7 | I10: Qtde Comprada | J10: =SUMIFS(D4:D28,C4:C28,"COMPRA") -> 120
B11: 45341 | C11: COMPRA | D11: 14 | E11: 26.1 | F11: 0 | G11: =E11*D11 -> 365.4 | I11: Qtde Vendida | J11: =SUMIFS(D4:D28,C4:C28,"VENDA") -> 0
B12: 45453 | C12: COMPRA | D12: 5 | E12: 29.74 | F12: 0 | G12: =E12*D12 -> 148.7 | I12: Qtde em Carteira | J12: =J10-J11 -> 120
B13: 45505 | C13: COMPRA | D13: 3 | E13: 30.75 | F13: 0 | G13: =E13*D13 -> 92.25 | I13: Valor das Compras | J13: =SUMIFS(G4:G28,C4:C28,"COMPRA") -> 3979.35
B14: 45595 | C14: COMPRA | D14: 16 | E14: 38.75 | F14: 0 | G14: =E14*D14 -> 620 | I14: Valor das Vendas | J14: =SUMIFS(E4:E28,C4:C28,"VENDA") -> 0
B15: 45628 | C15: COMPRA | D15: 4 | E15: 37.52 | F15: 0 | G15: =E15*D15 -> 150.08 | I15: Total de Taxas | J15: =SUM(F4:F28) -> 0
B16: 45667 | C16: COMPRA | D16: 6 | E16: 36.4 | F16: 0 | G16: =E16*D16 -> 218.4 | I16: Preço Médio | J16: =IF(J10<>0,((J13+J15)/J10),"") -> 33.16125
B17: 45758 | C17: COMPRA | D17: 5 | E17: 39.18 | F17: 0 | G17: =E17*D17 -> 195.9
B18: 46000 | C18: COMPRA | D18: 5 | E18: 48.64 | F18: 0 | G18: =E18*D18 -> 243.2
B19: 46051 | C19: COMPRA | D19: 5 | E19: 49.44 | F19: 0 | G19: =E19*D19 -> 247.2
B20: 46087 | C20: COMPRA | D20: 7 | E20: 48.81 | F20: 0 | G20: =E20*D20 -> 341.67
B21: 46205 | C21: COMPRA | D21: 6 | E21: 53.26 | F21: 0 | G21: =E21*D21 -> 319.56
G22: =E22*D22 -> 0
G23: =E23*D23 -> 0
G24: =E24*D24 -> 0
G25: =E25*D25 -> 0
G26: =E26*D26 -> 0
G27: =E27*D27 -> 0
G28: =E28*D28 -> 0

Sheet HYPE3
B2: ID | C2: HYPE3 | D2: Nome do Ativo | F2: =IFERROR(__xludf.DUMMYFUNCTION("IF(C2="""","""",GOOGLEFINANCE(C2,""Name""))"),"Hypera SA") -> Hypera SA
B3: Data | C3: Operação | D3: Qtde | E3: Valor unitário | F3: Taxas/Impostos | G3: Valor da operação | H3: Gráfico | K3: Dias graf
B4: 44628 | C4: COMPRA | D4: 3 | E4: 32.6 | F4: 0 | G4: =E4*D4 -> 97.8 | H4: =IFERROR(__xludf.DUMMYFUNCTION("IF(C2="""","""",SPARKLINE(GOOGLEFINANCE(C2,""price"",TODAY()-K4,TODAY())))"),"") | K4: 30
B5: 44743 | C5: COMPRA | D5: 3 | E5: 37.53 | F5: 0 | G5: =E5*D5 -> 112.59
B6: 44841 | C6: COMPRA | D6: 2 | E6: 46.32 | F6: 0 | G6: =E6*D6 -> 92.64
B7: 44935 | C7: COMPRA | D7: 2 | E7: 43.2 | F7: 0 | G7: =E7*D7 -> 86.4
B8: 44999 | C8: COMPRA | D8: 8 | E8: 40.58 | F8: 0 | G8: =E8*D8 -> 324.64
B9: 45246 | C9: COMPRA | D9: 5 | E9: 33.83 | F9: 0 | G9: =E9*D9 -> 169.15
B10: 45246 | C10: COMPRA | D10: 7 | E10: 34.05 | F10: 0 | G10: =E10*D10 -> 238.35 | I10: Qtde Comprada | J10: =SUMIFS(D4:D29,C4:C29,"COMPRA") -> 211
B11: 45341 | C11: COMPRA | D11: 7 | E11: 32.59 | F11: 0 | G11: =E11*D11 -> 228.13 | I11: Qtde Vendida | J11: =SUMIFS(D4:D29,C4:C29,"VENDA") -> 0
B12: 45426 | C12: COMPRA | D12: 3 | E12: 30.39 | F12: 0 | G12: =E12*D12 -> 91.17 | I12: Qtde em Carteira | J12: =J10-J11 -> 211
B13: 45453 | C13: COMPRA | D13: 6 | E13: 28.7 | F13: 0 | G13: =E13*D13 -> 172.2 | I13: Valor das Compras | J13: =SUMIFS(G4:G29,C4:C29,"COMPRA") -> 5404.46
B14: 45505 | C14: COMPRA | D14: 4 | E14: 28.47 | F14: 0 | G14: =E14*D14 -> 113.88 | I14: Valor das Vendas | J14: =SUMIFS(E4:E29,C4:C29,"VENDA") -> 0
B15: 45505 | C15: COMPRA | D15: 8 | E15: 28.33 | F15: 0 | G15: =E15*D15 -> 226.64 | I15: Total de Taxas | J15: =SUM(F4:F29) -> 0
B16: 45551 | C16: COMPRA | D16: 6 | E16: 29.02 | F16: 0 | G16: =E16*D16 -> 174.12 | I16: Preço Médio | J16: =IF(J10<>0,((J13+J15)/J10),"") -> 25.613554
B17: 45595 | C17: COMPRA | D17: 26 | E17: 24.04 | F17: 0 | G17: =E17*D17 -> 625.04
B18: 45628 | C18: COMPRA | D18: 8 | E18: 19.84 | F18: 0 | G18: =E18*D18 -> 158.72
B19: 45667 | C19: COMPRA | D19: 11 | E19: 17.93 | F19: 0 | G19: =E19*D19 -> 197.23
B20: 45758 | C20: COMPRA | D20: 7 | E20: 19.42 | F20: 0 | G20: =E20*D20 -> 135.94
B21: 45848 | C21: COMPRA | D21: 10 | E21: 26.79 | F21: 0 | G21: =E21*D21 -> 267.9
B22: 45922 | C22: COMPRA | D22: 12 | E22: 23.35 | F22: 0 | G22: =E22*D22 -> 280.2
B23: 45939 | C23: COMPRA | D23: 22 | E23: 20.82 | F23: 0 | G23: =E23*D23 -> 458.04
B24: 46000 | C24: COMPRA | D24: 9 | E24: 24.38 | F24: 0 | G24: =E24*D24 -> 219.42
B25: 46051 | C25: COMPRA | D25: 10 | E25: 25.41 | F25: 0 | G25: =E25*D25 -> 254.1
B26: 46087 | C26: COMPRA | D26: 16 | E26: 21.78 | F26: 0 | G26: =E26*D26 -> 348.48
B27: 46205 | C27: COMPRA | D27: 16 | E27: 20.73 | F27: 0 | G27: =E27*D27 -> 331.68

Sheet B3SA3
B2: ID | C2: B3SA3 | D2: Nome do Ativo | F2: =IFERROR(__xludf.DUMMYFUNCTION("IF(C2="""","""",GOOGLEFINANCE(C2,""Name""))"),"B3 SA Brasil Bolsa Balcao") -> B3 SA Brasil Bolsa Balcao
B3: Data | C3: Operação | D3: Qtde | E3: Valor unitário | F3: Taxas/Impostos | G3: Valor da operação | H3: Gráfico | K3: Dias graf
B4: 44628 | C4: COMPRA | D4: 8 | E4: 13.91 | F4: 0 | G4: =E4*D4 -> 111.28 | H4: =IFERROR(__xludf.DUMMYFUNCTION("IF(C2="""","""",SPARKLINE(GOOGLEFINANCE(C2,""price"",TODAY()-K4,TODAY())))"),"") | K4: 90
B5: 44655 | C5: COMPRA | D5: 6 | E5: 15.98 | F5: 0 | G5: =E5*D5 -> 95.88
